Get devices for measurement successfully!
#### # Linerar 192 768 3072
/root/siton-data-guoguodata/tcj/brainstorm_project/brainstorm/.cache/log/kernel_tune/NVIDIA_A800_80GB_PCIe/Linear_forward_input_0_192_768_output_0_192_3072_in_features_768_out_features_3072.json
/root/siton-data-guoguodata/tcj/brainstorm_project/brainstorm/.cache/log/kernel_tune/NVIDIA_A800_80GB_PCIe/Linear_forward_input_0_192_768_output_0_192_3072_in_features_768_out_features_3072.json
#### Find tuned kernel, pass
linear_kernel<function CUDACompiler.create_raw.<locals>.func at 0x7fe3b6920c10>
Traceback (most recent call last):
  File "linear_3078_768.py", line 108, in <module>
    time = Timer(
  File "/root/siton-data-guoguodata/tcj/miniconda3/lib/python3.8/site-packages/torch/utils/benchmark/utils/timer.py", line 266, in timeit
    self._timeit(number=max(int(number // 100), 2))
  File "/root/siton-data-guoguodata/tcj/miniconda3/lib/python3.8/site-packages/torch/utils/benchmark/utils/timer.py", line 256, in _timeit
    return max(self._timer.timeit(number), 1e-9)
  File "/root/siton-data-guoguodata/tcj/miniconda3/lib/python3.8/timeit.py", line 177, in timeit
    timing = self.inner(it, self.timer)
  File "<timeit-src>", line 6, in inner
  File "/root/siton-data-guoguodata/tcj/brainstorm_project/brainstorm/python/brt/jit/compiler.py", line 21, in func
    jit.static_invoke(inputs, extra, __ctx__)
TypeError: static_invoke(): incompatible function arguments. The following argument types are supported:
    1. (arg0: List[at::Tensor], arg1: List[int], arg2: int) -> None

Invoked with: ([tensor([[-2.5738, -0.1680, -1.4711,  ..., -0.7844, -0.7644, -0.5175],
        [-0.8556, -0.6930, -0.0902,  ...,  0.7756, -0.9551, -2.7321],
        [-0.3265,  0.3043, -0.0465,  ...,  0.0636, -0.1423, -1.7077],
        ...,
        [-0.2251,  0.4516, -0.1571,  ..., -1.3428,  0.7376,  0.2409],
        [ 1.1433, -0.1603, -0.0431,  ..., -0.1035, -0.9811, -0.0907],
        [-0.6747, -1.2828, -0.6948,  ...,  0.6271, -1.6441, -0.3102]],
       device='cuda:0')], [Parameter containing:
tensor([[ 1.2669e-02, -2.3407e-02,  1.7394e-02,  ..., -3.2010e-02,
          3.8813e-05, -2.7877e-02],
        [ 1.6756e-02,  2.1630e-02,  1.9343e-02,  ..., -1.6328e-03,
         -3.3521e-02,  6.0715e-03],
        [-1.0481e-03,  1.2376e-02, -1.6066e-02,  ...,  2.8942e-02,
          1.2332e-03,  2.2845e-03],
        ...,
        [ 1.8394e-02, -1.4287e-02,  4.6093e-03,  ...,  9.2506e-03,
          8.0890e-03,  5.7844e-03],
        [ 2.2647e-02, -1.6068e-02,  1.7871e-02,  ..., -2.4182e-03,
          4.7898e-03,  3.4184e-02],
        [ 2.2416e-02, -2.6504e-02, -1.3892e-02,  ...,  3.3885e-02,
         -5.7624e-03, -7.4578e-03]], device='cuda:0', requires_grad=True)], [tensor([[0., 0., 0.,  ..., 0., 0., 0.],
        [0., 0., 0.,  ..., 0., 0., 0.],
        [0., 0., 0.,  ..., 0., 0., 0.],
        ...,
        [0., 0., 0.,  ..., 0., 0., 0.],
        [0., 0., 0.,  ..., 0., 0., 0.],
        [0., 0., 0.,  ..., 0., 0., 0.]], device='cuda:0')], [None]), [], 0
Exception ignored in: <function LocalRPCMeasureContext.__del__ at 0x7fe278756790>
Traceback (most recent call last):
  File "/root/siton-data-guoguodata/tcj/miniconda3/lib/python3.8/site-packages/tvm/auto_scheduler/measure.py", line 588, in __del__
  File "/root/siton-data-guoguodata/tcj/miniconda3/lib/python3.8/site-packages/tvm/rpc/tracker.py", line 468, in terminate
  File "/root/siton-data-guoguodata/tcj/miniconda3/lib/python3.8/site-packages/tvm/rpc/tracker.py", line 455, in _stop_tracker
AttributeError: 'NoneType' object has no attribute 'socket'
Exception ignored in: <function Tracker.__del__ at 0x7fe276eff430>
Traceback (most recent call last):
  File "/root/siton-data-guoguodata/tcj/miniconda3/lib/python3.8/site-packages/tvm/rpc/tracker.py", line 477, in __del__
  File "/root/siton-data-guoguodata/tcj/miniconda3/lib/python3.8/site-packages/tvm/rpc/tracker.py", line 468, in terminate
  File "/root/siton-data-guoguodata/tcj/miniconda3/lib/python3.8/site-packages/tvm/rpc/tracker.py", line 455, in _stop_tracker
AttributeError: 'NoneType' object has no attribute 'socket'
Exception ignored in: <function Server.__del__ at 0x7fe3bb865ca0>
Traceback (most recent call last):
  File "/root/siton-data-guoguodata/tcj/miniconda3/lib/python3.8/site-packages/tvm/rpc/server.py", line 493, in __del__
  File "/root/siton-data-guoguodata/tcj/miniconda3/lib/python3.8/site-packages/tvm/rpc/server.py", line 489, in terminate
  File "/root/siton-data-guoguodata/tcj/miniconda3/lib/python3.8/site-packages/tvm/contrib/popen_pool.py", line 137, in kill
  File "/root/siton-data-guoguodata/tcj/miniconda3/lib/python3.8/site-packages/tvm/contrib/popen_pool.py", line 43, in kill_child_processes
ImportError: sys.meta_path is None, Python is likely shutting down
