Get devices for measurement successfully!
#### # Linerar 96 768 3072
/root/siton-data-guoguodata/tcj/brainstorm_project/brainstorm/.cache/log/kernel_tune/NVIDIA_A800_80GB_PCIe/Linear_forward_input_0_96_768_output_0_96_3072_in_features_768_out_features_3072.json
/root/siton-data-guoguodata/tcj/brainstorm_project/brainstorm/.cache/log/kernel_tune/NVIDIA_A800_80GB_PCIe/Linear_forward_input_0_96_768_output_0_96_3072_in_features_768_out_features_3072.json
#### Find tuned kernel, pass
Traceback (most recent call last):
  File "linear_3078_768.py", line 93, in <module>
    linear_kernel = make_jit_kernel(
  File "/root/siton-data-guoguodata/tcj/brainstorm_project/brainstorm/python/brt/jit/factory.py", line 36, in make_jit_kernel
    return ModuleFactory.make_kernel(
  File "/root/siton-data-guoguodata/tcj/brainstorm_project/brainstorm/python/brt/jit/factory.py", line 91, in make_kernel
    return jit_module.make_kernel(
  File "/root/siton-data-guoguodata/tcj/brainstorm_project/brainstorm/python/brt/jit/modules/base.py", line 40, in make_kernel
    global_kernel = self._make_global_kernel(
  File "/root/siton-data-guoguodata/tcj/brainstorm_project/brainstorm/python/brt/jit/modules/linear.py", line 42, in _make_global_kernel
    return ModuleKernel(
  File "/root/siton-data-guoguodata/tcj/brainstorm_project/brainstorm/python/brt/jit/codegen/module.py", line 246, in load_from_db
    raise ValueError(
ValueError: No kernel found in database with identifier = '{"device_name": "NVIDIA_A800_80GB_PCIe", "input_infos": {"input_0": [96, 768]}, "method": "forward", "op_type": "Linear", "output_infos": {"output_0": [96, 3072]}, "parameters": {"in_features": 768, "out_features": 3072}}', objective_func = 'fastest', self.platform ='CUDA_GPU', self.platform ='CUDA_GPU', rank =1
Exception ignored in: <function LocalRPCMeasureContext.__del__ at 0x7fb6c0482670>
Traceback (most recent call last):
  File "/root/siton-data-guoguodata/tcj/miniconda3/lib/python3.8/site-packages/tvm/auto_scheduler/measure.py", line 588, in __del__
  File "/root/siton-data-guoguodata/tcj/miniconda3/lib/python3.8/site-packages/tvm/rpc/tracker.py", line 468, in terminate
  File "/root/siton-data-guoguodata/tcj/miniconda3/lib/python3.8/site-packages/tvm/rpc/tracker.py", line 455, in _stop_tracker
AttributeError: 'NoneType' object has no attribute 'socket'
Exception ignored in: <function Tracker.__del__ at 0x7fb630c0f310>
Traceback (most recent call last):
  File "/root/siton-data-guoguodata/tcj/miniconda3/lib/python3.8/site-packages/tvm/rpc/tracker.py", line 477, in __del__
  File "/root/siton-data-guoguodata/tcj/miniconda3/lib/python3.8/site-packages/tvm/rpc/tracker.py", line 468, in terminate
  File "/root/siton-data-guoguodata/tcj/miniconda3/lib/python3.8/site-packages/tvm/rpc/tracker.py", line 455, in _stop_tracker
AttributeError: 'NoneType' object has no attribute 'socket'
Exception ignored in: <function Server.__del__ at 0x7fb775574b80>
Traceback (most recent call last):
  File "/root/siton-data-guoguodata/tcj/miniconda3/lib/python3.8/site-packages/tvm/rpc/server.py", line 493, in __del__
  File "/root/siton-data-guoguodata/tcj/miniconda3/lib/python3.8/site-packages/tvm/rpc/server.py", line 489, in terminate
  File "/root/siton-data-guoguodata/tcj/miniconda3/lib/python3.8/site-packages/tvm/contrib/popen_pool.py", line 137, in kill
  File "/root/siton-data-guoguodata/tcj/miniconda3/lib/python3.8/site-packages/tvm/contrib/popen_pool.py", line 43, in kill_child_processes
ImportError: sys.meta_path is None, Python is likely shutting down
